[19/12/2017 21:08] ERROR red load_cogs 573: ffmpeg isn't installed.
Consult the guide for your operating system and do ALL the steps in order.
https://twentysix26.github.io/Red-Docs/
Traceback (most recent call last):
  File "C:\Users\luke-pc\Desktop\Red-DiscordBot-develop\Red-DiscordBot-develop\red.py", line 570, in load_cogs
    owner_cog._load_cog(extension)
  File "C:\Users\luke-pc\Desktop\Red-DiscordBot-develop\Red-DiscordBot-develop\cogs\owner.py", line 948, in _load_cog
    self.bot.load_extension(mod_obj.__name__)
  File "lib\discord\ext\commands\bot.py", line 738, in load_extension
    lib.setup(self)
  File "C:\Users\luke-pc\Desktop\Red-DiscordBot-develop\Red-DiscordBot-develop\cogs\audio.py", line 2372, in setup
    "".format(msg))
RuntimeError: ffmpeg isn't installed.
Consult the guide for your operating system and do ALL the steps in order.
https://twentysix26.github.io/Red-Docs/

[20/12/2017 08:42] ERROR red on_command_error 369: Exception in command 'join'
Traceback (most recent call last):
  File "lib\discord\ext\commands\core.py", line 50, in wrapped
    ret = yield from coro(*args, **kwargs)
  File "C:\Users\luke-pc\Desktop\Red-DiscordBot-develop\Red-DiscordBot-develop\cogs\owner.py", line 732, in join
    await self.bot.whisper("Invite URL: " + self.bot.oauth_url)
  File "lib\discord\ext\commands\bot.py", line 309, in _augmented_msg
    msg = yield from coro
  File "C:\Users\luke-pc\Desktop\Red-DiscordBot-develop\Red-DiscordBot-develop\red.py", line 92, in send_message
    return await super().send_message(*args, **kwargs)
  File "lib\discord\client.py", line 1151, in send_message
    data = yield from self.http.send_message(channel_id, content, guild_id=guild_id, tts=tts, embed=embed)
  File "lib\discord\http.py", line 200, in request
    raise HTTPException(r, data)
discord.errors.HTTPException: Gateway Time-out (status code: 504): <html>
<head><title>504 Gateway Time-out</title></head>
<body bgcolor="white">
<center><h1>504 Gateway Time-out</h1></center>
<hr><center>cloudflare-nginx</center>
</body>
</html>

[20/12/2017 10:15] ERROR owner avatar 494: Unsupported image type given
Traceback (most recent call last):
  File "C:\Users\luke-pc\Desktop\Red-DiscordBot-develop\Red-DiscordBot-develop\cogs\owner.py", line 488, in avatar
    await self.bot.edit_profile(self.bot.settings.password, avatar=data)
  File "lib\discord\client.py", line 1840, in edit_profile
    avatar = utils._bytes_to_base64_data(avatar_bytes)
  File "lib\discord\utils.py", line 247, in _bytes_to_base64_data
    mime = _get_mime_type_for_image(data)
  File "lib\discord\utils.py", line 243, in _get_mime_type_for_image
    raise InvalidArgument('Unsupported image type given')
discord.errors.InvalidArgument: Unsupported image type given
[20/12/2017 10:15] ERROR owner avatar 494: Unsupported image type given
Traceback (most recent call last):
  File "C:\Users\luke-pc\Desktop\Red-DiscordBot-develop\Red-DiscordBot-develop\cogs\owner.py", line 488, in avatar
    await self.bot.edit_profile(self.bot.settings.password, avatar=data)
  File "lib\discord\client.py", line 1840, in edit_profile
    avatar = utils._bytes_to_base64_data(avatar_bytes)
  File "lib\discord\utils.py", line 247, in _bytes_to_base64_data
    mime = _get_mime_type_for_image(data)
  File "lib\discord\utils.py", line 243, in _get_mime_type_for_image
    raise InvalidArgument('Unsupported image type given')
discord.errors.InvalidArgument: Unsupported image type given
[20/12/2017 11:01] ERROR red load_cogs 573: HTTPSConnectionPool(host='api.imgur.com', port=443): Max retries exceeded with url: /3/credits (Caused by NewConnectionError('<urllib3.connection.VerifiedHTTPSConnection object at 0x0000003FA463B470>: Failed to establish a new connection: [WinError 10060] A connection attempt failed because the connected party did not properly respond after a period of time, or established connection failed because connected host has failed to respond',))
Traceback (most recent call last):
  File "lib\urllib3\connection.py", line 141, in _new_conn
    (self.host, self.port), self.timeout, **extra_kw)
  File "lib\urllib3\util\connection.py", line 83, in create_connection
    raise err
  File "lib\urllib3\util\connection.py", line 73, in create_connection
    sock.connect(sa)
TimeoutError: [WinError 10060] A connection attempt failed because the connected party did not properly respond after a period of time, or established connection failed because connected host has failed to respond

During handling of the above exception, another exception occurred:

Traceback (most recent call last):
  File "lib\urllib3\connectionpool.py", line 601, in urlopen
    chunked=chunked)
  File "lib\urllib3\connectionpool.py", line 346, in _make_request
    self._validate_conn(conn)
  File "lib\urllib3\connectionpool.py", line 850, in _validate_conn
    conn.connect()
  File "lib\urllib3\connection.py", line 284, in connect
    conn = self._new_conn()
  File "lib\urllib3\connection.py", line 150, in _new_conn
    self, "Failed to establish a new connection: %s" % e)
urllib3.exceptions.NewConnectionError: <urllib3.connection.VerifiedHTTPSConnection object at 0x0000003FA463B470>: Failed to establish a new connection: [WinError 10060] A connection attempt failed because the connected party did not properly respond after a period of time, or established connection failed because connected host has failed to respond

During handling of the above exception, another exception occurred:

Traceback (most recent call last):
  File "lib\requests\adapters.py", line 440, in send
    timeout=timeout
  File "lib\urllib3\connectionpool.py", line 639, in urlopen
    _stacktrace=sys.exc_info()[2])
  File "lib\urllib3\util\retry.py", line 388, in increment
    raise MaxRetryError(_pool, url, error or ResponseError(cause))
urllib3.exceptions.MaxRetryError: HTTPSConnectionPool(host='api.imgur.com', port=443): Max retries exceeded with url: /3/credits (Caused by NewConnectionError('<urllib3.connection.VerifiedHTTPSConnection object at 0x0000003FA463B470>: Failed to establish a new connection: [WinError 10060] A connection attempt failed because the connected party did not properly respond after a period of time, or established connection failed because connected host has failed to respond',))

During handling of the above exception, another exception occurred:

Traceback (most recent call last):
  File "C:\Users\luke-pc\Desktop\Red-DiscordBot-develop\Red-DiscordBot-develop\red.py", line 570, in load_cogs
    owner_cog._load_cog(extension)
  File "C:\Users\luke-pc\Desktop\Red-DiscordBot-develop\Red-DiscordBot-develop\cogs\owner.py", line 948, in _load_cog
    self.bot.load_extension(mod_obj.__name__)
  File "lib\discord\ext\commands\bot.py", line 738, in load_extension
    lib.setup(self)
  File "C:\Users\luke-pc\Desktop\Red-DiscordBot-develop\Red-DiscordBot-develop\cogs\image.py", line 168, in setup
    bot.add_cog(Image(bot))
  File "C:\Users\luke-pc\Desktop\Red-DiscordBot-develop\Red-DiscordBot-develop\cogs\image.py", line 22, in __init__
    self.imgur = ImgurClient(CLIENT_ID, CLIENT_SECRET)
  File "lib\imgurpython\client.py", line 85, in __init__
    self.credits = self.get_credits()
  File "lib\imgurpython\client.py", line 94, in get_credits
    return self.make_request('GET', 'credits', None, True)
  File "lib\imgurpython\client.py", line 131, in make_request
    response = method_to_call(url, headers=header, params=data, data=data)
  File "lib\requests\api.py", line 72, in get
    return request('get', url, params=params, **kwargs)
  File "lib\requests\api.py", line 58, in request
    return session.request(method=method, url=url, **kwargs)
  File "lib\requests\sessions.py", line 508, in request
    resp = self.send(prep, **send_kwargs)
  File "lib\requests\sessions.py", line 618, in send
    r = adapter.send(request, **kwargs)
  File "lib\requests\adapters.py", line 508, in send
    raise ConnectionError(e, request=request)
requests.exceptions.ConnectionError: HTTPSConnectionPool(host='api.imgur.com', port=443): Max retries exceeded with url: /3/credits (Caused by NewConnectionError('<urllib3.connection.VerifiedHTTPSConnection object at 0x0000003FA463B470>: Failed to establish a new connection: [WinError 10060] A connection attempt failed because the connected party did not properly respond after a period of time, or established connection failed because connected host has failed to respond',))
[20/12/2017 11:02] ERROR red <module> 634: Fatal exception, attempting graceful logout
Traceback (most recent call last):
  File "lib\aiohttp\connector.py", line 304, in connect
    yield from self._create_connection(req)
  File "lib\aiohttp\connector.py", line 578, in _create_connection
    transport, proto = yield from self._create_direct_connection(req)
  File "lib\aiohttp\connector.py", line 589, in _create_direct_connection
    hosts = yield from self._resolve_host(req.host, req.port)
  File "lib\aiohttp\connector.py", line 561, in _resolve_host
    self._resolver.resolve(host, port, family=self._family)
  File "lib\aiohttp\resolver.py", line 29, in resolve
    host, port, type=socket.SOCK_STREAM, family=family)
  File "C:\Users\luke-pc\AppData\Local\Programs\Python\Python35\lib\asyncio\futures.py", line 361, in __iter__
    yield self  # This tells Task to wait for completion.
  File "C:\Users\luke-pc\AppData\Local\Programs\Python\Python35\lib\asyncio\tasks.py", line 296, in _wakeup
    future.result()
  File "C:\Users\luke-pc\AppData\Local\Programs\Python\Python35\lib\asyncio\futures.py", line 274, in result
    raise self._exception
  File "C:\Users\luke-pc\AppData\Local\Programs\Python\Python35\lib\concurrent\futures\thread.py", line 55, in run
    result = self.fn(*self.args, **self.kwargs)
  File "C:\Users\luke-pc\AppData\Local\Programs\Python\Python35\lib\socket.py", line 732, in getaddrinfo
    for res in _socket.getaddrinfo(host, port, family, type, proto, flags):
socket.gaierror: [Errno 11001] getaddrinfo failed

The above exception was the direct cause of the following exception:

Traceback (most recent call last):
  File "C:\Users\luke-pc\Desktop\Red-DiscordBot-develop\Red-DiscordBot-develop\red.py", line 614, in <module>
    loop.run_until_complete(main(bot))
  File "C:\Users\luke-pc\AppData\Local\Programs\Python\Python35\lib\asyncio\base_events.py", line 387, in run_until_complete
    return future.result()
  File "C:\Users\luke-pc\AppData\Local\Programs\Python\Python35\lib\asyncio\futures.py", line 274, in result
    raise self._exception
  File "C:\Users\luke-pc\AppData\Local\Programs\Python\Python35\lib\asyncio\tasks.py", line 241, in _step
    result = coro.throw(exc)
  File "C:\Users\luke-pc\Desktop\Red-DiscordBot-develop\Red-DiscordBot-develop\red.py", line 599, in main
    bot=not bot.settings.self_bot)
  File "lib\discord\client.py", line 416, in login
    yield from getattr(self, '_login_' + str(n))(*args, **kwargs)
  File "lib\discord\client.py", line 346, in _login_1
    data = yield from self.http.static_login(token, bot=is_bot)
  File "lib\discord\http.py", line 258, in static_login
    data = yield from self.request(Route('GET', '/users/@me'))
  File "lib\discord\http.py", line 137, in request
    r = yield from self.session.request(method, url, **kwargs)
  File "lib\aiohttp\client.py", line 555, in __iter__
    resp = yield from self._coro
  File "lib\aiohttp\client.py", line 198, in _request
    conn = yield from self._connector.connect(req)
  File "lib\aiohttp\connector.py", line 314, in connect
    .format(key, exc.strerror)) from exc
aiohttp.errors.ClientOSError: [Errno 11001] Cannot connect to host discordapp.com:443 ssl:True [getaddrinfo failed]
[20/12/2017 11:41] ERROR red on_command_error 369: Exception in command 'send dm'
Traceback (most recent call last):
  File "lib\discord\ext\commands\core.py", line 50, in wrapped
    ret = yield from coro(*args, **kwargs)
  File "C:\Users\luke-pc\Desktop\Red-DiscordBot-develop\Red-DiscordBot-develop\cogs\say.py", line 111, in dm
    if server.id not in self.settings:
AttributeError: 'NoneType' object has no attribute 'id'
[20/12/2017 12:59] ERROR red on_command_error 369: Exception in command 'send dm'
Traceback (most recent call last):
  File "lib\discord\ext\commands\core.py", line 50, in wrapped
    ret = yield from coro(*args, **kwargs)
  File "C:\Users\luke-pc\Desktop\Red-DiscordBot-develop\Red-DiscordBot-develop\cogs\say.py", line 111, in dm
    if server.id not in self.settings:
AttributeError: 'NoneType' object has no attribute 'id'
[31/12/2017 07:56] ERROR red <module> 634: Fatal exception, attempting graceful logout
Traceback (most recent call last):
  File "C:\Users\Zak\Documents\Red-DiscordBot-develop\Red-DiscordBot-develop\Red-DiscordBot-develop\red.py", line 614, in <module>
    loop.run_until_complete(main(bot))
  File "C:\Users\Zak\AppData\Local\Programs\Python\Python35\lib\asyncio\base_events.py", line 467, in run_until_complete
    return future.result()
  File "C:\Users\Zak\AppData\Local\Programs\Python\Python35\lib\asyncio\futures.py", line 294, in result
    raise self._exception
  File "C:\Users\Zak\AppData\Local\Programs\Python\Python35\lib\asyncio\tasks.py", line 240, in _step
    result = coro.send(None)
  File "C:\Users\Zak\Documents\Red-DiscordBot-develop\Red-DiscordBot-develop\Red-DiscordBot-develop\red.py", line 594, in main
    print("Logging into Discord...")
OSError: raw write() returned invalid length 50 (should have been between 0 and 25)
[31/12/2017 11:58] ERROR red on_command_error 369: Exception in command 'whisper'
Traceback (most recent call last):
  File "lib\discord\ext\commands\core.py", line 50, in wrapped
    ret = yield from coro(*args, **kwargs)
  File "C:\Users\Zak\Documents\Red-DiscordBot-develop\Red-DiscordBot-develop\Red-DiscordBot-develop\cogs\whisper.py", line 18, in whisper
    user = await self.bot.get_user_info(user_id)
  File "lib\discord\client.py", line 3317, in get_user_info
    data = yield from self.http.get_user_info(user_id)
  File "lib\discord\http.py", line 200, in request
    raise HTTPException(r, data)
discord.errors.HTTPException: BAD REQUEST (status code: 400)
[31/12/2017 11:58] ERROR red on_command_error 369: Exception in command 'whisper'
Traceback (most recent call last):
  File "lib\discord\ext\commands\core.py", line 50, in wrapped
    ret = yield from coro(*args, **kwargs)
  File "C:\Users\Zak\Documents\Red-DiscordBot-develop\Red-DiscordBot-develop\Red-DiscordBot-develop\cogs\whisper.py", line 18, in whisper
    user = await self.bot.get_user_info(user_id)
  File "lib\discord\client.py", line 3317, in get_user_info
    data = yield from self.http.get_user_info(user_id)
  File "lib\discord\http.py", line 200, in request
    raise HTTPException(r, data)
discord.errors.HTTPException: BAD REQUEST (status code: 400)
[31/12/2017 12:00] ERROR red on_command_error 369: Exception in command 'whisper'
Traceback (most recent call last):
  File "lib\discord\ext\commands\core.py", line 50, in wrapped
    ret = yield from coro(*args, **kwargs)
  File "C:\Users\Zak\Documents\Red-DiscordBot-develop\Red-DiscordBot-develop\Red-DiscordBot-develop\cogs\whisper.py", line 18, in whisper
    user = await self.bot.get_user_info(user_id)
  File "lib\discord\client.py", line 3317, in get_user_info
    data = yield from self.http.get_user_info(user_id)
  File "lib\discord\http.py", line 200, in request
    raise HTTPException(r, data)
discord.errors.HTTPException: BAD REQUEST (status code: 400)
[31/12/2017 12:00] ERROR red on_command_error 369: Exception in command 'whisper'
Traceback (most recent call last):
  File "lib\discord\ext\commands\core.py", line 50, in wrapped
    ret = yield from coro(*args, **kwargs)
  File "C:\Users\Zak\Documents\Red-DiscordBot-develop\Red-DiscordBot-develop\Red-DiscordBot-develop\cogs\whisper.py", line 18, in whisper
    user = await self.bot.get_user_info(user_id)
  File "lib\discord\client.py", line 3317, in get_user_info
    data = yield from self.http.get_user_info(user_id)
  File "lib\discord\http.py", line 200, in request
    raise HTTPException(r, data)
discord.errors.HTTPException: BAD REQUEST (status code: 400)
[31/12/2017 12:16] ERROR red on_command_error 369: Exception in command 'whisper'
Traceback (most recent call last):
  File "lib\discord\ext\commands\core.py", line 50, in wrapped
    ret = yield from coro(*args, **kwargs)
  File "C:\Users\Zak\Documents\Red-DiscordBot-develop\Red-DiscordBot-develop\Red-DiscordBot-develop\cogs\whisper.py", line 18, in whisper
    user = await self.bot.get_user_info(user_id)
  File "lib\discord\client.py", line 3317, in get_user_info
    data = yield from self.http.get_user_info(user_id)
  File "lib\discord\http.py", line 198, in request
    raise NotFound(r, data)
discord.errors.NotFound: NOT FOUND (status code: 404): Unknown User
[31/12/2017 12:55] ERROR red <module> 634: Fatal exception, attempting graceful logout
Traceback (most recent call last):
  File "lib\aiohttp\connector.py", line 601, in _create_direct_connection
    local_addr=self._local_addr)
  File "C:\Users\Zak\AppData\Local\Programs\Python\Python35\lib\asyncio\base_events.py", line 776, in create_connection
    raise exceptions[0]
  File "C:\Users\Zak\AppData\Local\Programs\Python\Python35\lib\asyncio\base_events.py", line 763, in create_connection
    yield from self.sock_connect(sock, address)
  File "C:\Users\Zak\AppData\Local\Programs\Python\Python35\lib\asyncio\selector_events.py", line 451, in sock_connect
    return (yield from fut)
  File "C:\Users\Zak\AppData\Local\Programs\Python\Python35\lib\asyncio\futures.py", line 381, in __iter__
    yield self  # This tells Task to wait for completion.
  File "C:\Users\Zak\AppData\Local\Programs\Python\Python35\lib\asyncio\tasks.py", line 310, in _wakeup
    future.result()
  File "C:\Users\Zak\AppData\Local\Programs\Python\Python35\lib\asyncio\futures.py", line 294, in result
    raise self._exception
  File "C:\Users\Zak\AppData\Local\Programs\Python\Python35\lib\asyncio\selector_events.py", line 481, in _sock_connect_cb
    raise OSError(err, 'Connect call failed %s' % (address,))
TimeoutError: [Errno 10060] Connect call failed ('104.16.59.5', 443)

The above exception was the direct cause of the following exception:

Traceback (most recent call last):
  File "lib\aiohttp\connector.py", line 304, in connect
    yield from self._create_connection(req)
  File "lib\aiohttp\connector.py", line 578, in _create_connection
    transport, proto = yield from self._create_direct_connection(req)
  File "lib\aiohttp\connector.py", line 624, in _create_direct_connection
    (req.host, req.port, exc.strerror)) from exc
aiohttp.errors.ClientOSError: [Errno 10060] Can not connect to discordapp.com:443 [Connect call failed ('104.16.59.5', 443)]

The above exception was the direct cause of the following exception:

Traceback (most recent call last):
  File "C:\Users\Zak\Documents\Red-DiscordBot-develop\Red-DiscordBot-develop\Red-DiscordBot-develop\red.py", line 614, in <module>
    loop.run_until_complete(main(bot))
  File "C:\Users\Zak\AppData\Local\Programs\Python\Python35\lib\asyncio\base_events.py", line 467, in run_until_complete
    return future.result()
  File "C:\Users\Zak\AppData\Local\Programs\Python\Python35\lib\asyncio\futures.py", line 294, in result
    raise self._exception
  File "C:\Users\Zak\AppData\Local\Programs\Python\Python35\lib\asyncio\tasks.py", line 242, in _step
    result = coro.throw(exc)
  File "C:\Users\Zak\Documents\Red-DiscordBot-develop\Red-DiscordBot-develop\Red-DiscordBot-develop\red.py", line 603, in main
    yield from bot.connect()
  File "lib\discord\client.py", line 451, in connect
    self.ws = yield from DiscordWebSocket.from_client(self, resume=True)
  File "lib\discord\gateway.py", line 198, in from_client
    gateway = yield from client.http.get_gateway()
  File "lib\discord\http.py", line 633, in get_gateway
    data = yield from self.request(Route('GET', '/gateway'))
  File "lib\discord\http.py", line 137, in request
    r = yield from self.session.request(method, url, **kwargs)
  File "lib\aiohttp\client.py", line 555, in __iter__
    resp = yield from self._coro
  File "lib\aiohttp\client.py", line 198, in _request
    conn = yield from self._connector.connect(req)
  File "lib\aiohttp\connector.py", line 314, in connect
    .format(key, exc.strerror)) from exc
aiohttp.errors.ClientOSError: [Errno 10060] Cannot connect to host discordapp.com:443 ssl:True [Can not connect to discordapp.com:443 [Connect call failed ('104.16.59.5', 443)]]
[01/01/2018 18:26] ERROR red load_cogs 573: You must `pip3 install pillow` to use emotes
Traceback (most recent call last):
  File "C:\Users\Zak\Documents\Red-DiscordBot-develop\Red-DiscordBot-develop\Red-DiscordBot-develop\cogs\emotes.py", line 11, in <module>
    import PIL.Image as Image
  File "lib\PIL\Image.py", line 56, in <module>
    from . import _imaging as core
ImportError: cannot import name '_imaging'

The above exception was the direct cause of the following exception:

Traceback (most recent call last):
  File "C:\Users\Zak\Documents\Red-DiscordBot-develop\Red-DiscordBot-develop\Red-DiscordBot-develop\red.py", line 570, in load_cogs
    owner_cog._load_cog(extension)
  File "C:\Users\Zak\Documents\Red-DiscordBot-develop\Red-DiscordBot-develop\Red-DiscordBot-develop\cogs\owner.py", line 946, in _load_cog
    mod_obj = importlib.import_module(cogname)
  File "C:\Users\Zak\AppData\Local\Programs\Python\Python36-32\lib\importlib\__init__.py", line 126, in import_module
    return _bootstrap._gcd_import(name[level:], package, level)
  File "<frozen importlib._bootstrap>", line 994, in _gcd_import
  File "<frozen importlib._bootstrap>", line 971, in _find_and_load
  File "<frozen importlib._bootstrap>", line 955, in _find_and_load_unlocked
  File "<frozen importlib._bootstrap>", line 665, in _load_unlocked
  File "<frozen importlib._bootstrap_external>", line 678, in exec_module
  File "<frozen importlib._bootstrap>", line 219, in _call_with_frames_removed
  File "C:\Users\Zak\Documents\Red-DiscordBot-develop\Red-DiscordBot-develop\Red-DiscordBot-develop\cogs\emotes.py", line 13, in <module>
    raise RuntimeError("You must `pip3 install pillow` to use emotes") from e
RuntimeError: You must `pip3 install pillow` to use emotes
[01/01/2018 22:34] ERROR red <module> 616: Traceback (most recent call last):
  File "lib\discord\http.py", line 258, in static_login
    data = yield from self.request(Route('GET', '/users/@me'))
  File "lib\discord\http.py", line 200, in request
    raise HTTPException(r, data)
discord.errors.HTTPException: UNAUTHORIZED (status code: 401): 401: Unauthorized

The above exception was the direct cause of the following exception:

Traceback (most recent call last):
  File "C:\Users\Zak\Documents\Red-DiscordBot-develop\Red-DiscordBot-develop\Red-DiscordBot-develop\red.py", line 614, in <module>
    loop.run_until_complete(main(bot))
  File "C:\Users\Zak\AppData\Local\Programs\Python\Python36-32\lib\asyncio\base_events.py", line 467, in run_until_complete
    return future.result()
  File "C:\Users\Zak\Documents\Red-DiscordBot-develop\Red-DiscordBot-develop\Red-DiscordBot-develop\red.py", line 599, in main
    bot=not bot.settings.self_bot)
  File "lib\discord\client.py", line 416, in login
    yield from getattr(self, '_login_' + str(n))(*args, **kwargs)
  File "lib\discord\client.py", line 346, in _login_1
    data = yield from self.http.static_login(token, bot=is_bot)
  File "lib\discord\http.py", line 262, in static_login
    raise LoginFailure('Improper token has been passed.') from e
discord.errors.LoginFailure: Improper token has been passed.

[24/01/2018 17:42] ERROR red on_command_error 369: Exception in command 'whisper'
Traceback (most recent call last):
  File "lib\discord\ext\commands\core.py", line 50, in wrapped
    ret = yield from coro(*args, **kwargs)
  File "C:\Users\Zak\Documents\Red-DiscordBot-develop\Red-DiscordBot-develop\Red-DiscordBot-develop\cogs\whisper.py", line 18, in whisper
    user = await self.bot.get_user_info(user_id)
  File "lib\discord\client.py", line 3317, in get_user_info
    data = yield from self.http.get_user_info(user_id)
  File "lib\discord\http.py", line 200, in request
    raise HTTPException(r, data)
discord.errors.HTTPException: BAD REQUEST (status code: 400)
[26/01/2018 19:11] ERROR red load_cogs 573: Command say is already registered.
Traceback (most recent call last):
  File "C:\Users\Zak\Documents\Red-DiscordBot-develop\Red-DiscordBot-develop\Red-DiscordBot-develop\red.py", line 570, in load_cogs
    owner_cog._load_cog(extension)
  File "C:\Users\Zak\Documents\Red-DiscordBot-develop\Red-DiscordBot-develop\Red-DiscordBot-develop\cogs\owner.py", line 948, in _load_cog
    self.bot.load_extension(mod_obj.__name__)
  File "lib\discord\ext\commands\bot.py", line 738, in load_extension
    lib.setup(self)
  File "C:\Users\Zak\Documents\Red-DiscordBot-develop\Red-DiscordBot-develop\Red-DiscordBot-develop\cogs\say.py", line 48, in setup
    bot.add_cog(Say(bot))
  File "lib\discord\ext\commands\bot.py", line 655, in add_cog
    self.add_command(member)
  File "lib\discord\ext\commands\core.py", line 487, in add_command
    raise discord.ClientException('Command {0.name} is already registered.'.format(command))
discord.errors.ClientException: Command say is already registered.
[26/01/2018 19:13] ERROR owner avatar 494: Unsupported image type given
Traceback (most recent call last):
  File "C:\Users\Zak\Documents\Red-DiscordBot-develop\Red-DiscordBot-develop\Red-DiscordBot-develop\cogs\owner.py", line 488, in avatar
    await self.bot.edit_profile(self.bot.settings.password, avatar=data)
  File "lib\discord\client.py", line 1840, in edit_profile
    avatar = utils._bytes_to_base64_data(avatar_bytes)
  File "lib\discord\utils.py", line 247, in _bytes_to_base64_data
    mime = _get_mime_type_for_image(data)
  File "lib\discord\utils.py", line 243, in _get_mime_type_for_image
    raise InvalidArgument('Unsupported image type given')
discord.errors.InvalidArgument: Unsupported image type given
[26/01/2018 20:56] ERROR red on_command_error 369: Exception in command 'riftopen'
Traceback (most recent call last):
  File "lib\discord\ext\commands\core.py", line 50, in wrapped
    ret = yield from coro(*args, **kwargs)
  File "C:\Users\Zak\Documents\Red-DiscordBot-develop\Red-DiscordBot-develop\Red-DiscordBot-develop\cogs\rift.py", line 79, in riftopen
    del self.open_rifts[author]
KeyError: <discord.user.User object at 0x06F17C90>
[26/01/2018 21:09] ERROR red <module> 634: Fatal exception, attempting graceful logout
Traceback (most recent call last):
  File "lib\aiohttp\connector.py", line 601, in _create_direct_connection
    local_addr=self._local_addr)
  File "C:\Users\Zak\AppData\Local\Programs\Python\Python36-32\lib\asyncio\base_events.py", line 777, in create_connection
    raise exceptions[0]
  File "C:\Users\Zak\AppData\Local\Programs\Python\Python36-32\lib\asyncio\base_events.py", line 764, in create_connection
    yield from self.sock_connect(sock, address)
  File "C:\Users\Zak\AppData\Local\Programs\Python\Python36-32\lib\asyncio\selector_events.py", line 450, in sock_connect
    return (yield from fut)
  File "C:\Users\Zak\AppData\Local\Programs\Python\Python36-32\lib\asyncio\selector_events.py", line 480, in _sock_connect_cb
    raise OSError(err, 'Connect call failed %s' % (address,))
OSError: [Errno 10065] Connect call failed ('104.16.58.5', 443)

The above exception was the direct cause of the following exception:

Traceback (most recent call last):
  File "lib\aiohttp\connector.py", line 304, in connect
    yield from self._create_connection(req)
  File "lib\aiohttp\connector.py", line 578, in _create_connection
    transport, proto = yield from self._create_direct_connection(req)
  File "lib\aiohttp\connector.py", line 624, in _create_direct_connection
    (req.host, req.port, exc.strerror)) from exc
aiohttp.errors.ClientOSError: [Errno 10065] Can not connect to discordapp.com:443 [Connect call failed ('104.16.58.5', 443)]

The above exception was the direct cause of the following exception:

Traceback (most recent call last):
  File "C:\Users\Zak\Documents\Red-DiscordBot-develop\Red-DiscordBot-develop\Red-DiscordBot-develop\red.py", line 614, in <module>
    loop.run_until_complete(main(bot))
  File "C:\Users\Zak\AppData\Local\Programs\Python\Python36-32\lib\asyncio\base_events.py", line 467, in run_until_complete
    return future.result()
  File "C:\Users\Zak\Documents\Red-DiscordBot-develop\Red-DiscordBot-develop\Red-DiscordBot-develop\red.py", line 603, in main
    yield from bot.connect()
  File "lib\discord\client.py", line 451, in connect
    self.ws = yield from DiscordWebSocket.from_client(self, resume=True)
  File "lib\discord\gateway.py", line 198, in from_client
    gateway = yield from client.http.get_gateway()
  File "lib\discord\http.py", line 633, in get_gateway
    data = yield from self.request(Route('GET', '/gateway'))
  File "lib\discord\http.py", line 137, in request
    r = yield from self.session.request(method, url, **kwargs)
  File "lib\aiohttp\client.py", line 555, in __iter__
    resp = yield from self._coro
  File "lib\aiohttp\client.py", line 198, in _request
    conn = yield from self._connector.connect(req)
  File "lib\aiohttp\connector.py", line 314, in connect
    .format(key, exc.strerror)) from exc
aiohttp.errors.ClientOSError: [Errno 10065] Cannot connect to host discordapp.com:443 ssl:True [Can not connect to discordapp.com:443 [Connect call failed ('104.16.58.5', 443)]]
[27/01/2018 08:12] ERROR red on_command_error 369: Exception in command 'riftopen'
Traceback (most recent call last):
  File "lib\discord\ext\commands\core.py", line 50, in wrapped
    ret = yield from coro(*args, **kwargs)
  File "C:\Users\Zak\Documents\Red-DiscordBot-develop\Red-DiscordBot-develop\Red-DiscordBot-develop\cogs\rift.py", line 79, in riftopen
    del self.open_rifts[author]
KeyError: <discord.user.User object at 0x0297DD80>
[27/01/2018 08:30] ERROR red on_command_error 369: Exception in command 'riftopen'
Traceback (most recent call last):
  File "lib\discord\ext\commands\core.py", line 50, in wrapped
    ret = yield from coro(*args, **kwargs)
  File "C:\Users\Zak\Documents\Red-DiscordBot-develop\Red-DiscordBot-develop\Red-DiscordBot-develop\cogs\rift.py", line 79, in riftopen
    del self.open_rifts[author]
KeyError: <discord.member.Member object at 0x070B5D20>
[31/01/2018 18:14] ERROR red on_command_error 369: Exception in command 'chatter'
Traceback (most recent call last):
  File "lib\discord\ext\commands\core.py", line 50, in wrapped
    ret = yield from coro(*args, **kwargs)
  File "C:\Users\Zak\Documents\Red-DiscordBot-develop\Red-DiscordBot-develop\Red-DiscordBot-develop\cogs\Chatter.py", line 53, in chatter
    await self.bot.delete_message(msgInput)
  File "lib\discord\client.py", line 1262, in delete_message
    yield from self.http.delete_message(channel.id, message.id, guild_id)
  File "lib\discord\http.py", line 196, in request
    raise Forbidden(r, data)
discord.errors.Forbidden: FORBIDDEN (status code: 403): Cannot execute action on a DM channel
[31/01/2018 18:15] ERROR red on_command_error 369: Exception in command 'chatter'
Traceback (most recent call last):
  File "lib\discord\ext\commands\core.py", line 50, in wrapped
    ret = yield from coro(*args, **kwargs)
  File "C:\Users\Zak\Documents\Red-DiscordBot-develop\Red-DiscordBot-develop\Red-DiscordBot-develop\cogs\Chatter.py", line 67, in chatter
    await self.bot.delete_message(msgInput)
  File "lib\discord\client.py", line 1262, in delete_message
    yield from self.http.delete_message(channel.id, message.id, guild_id)
  File "lib\discord\http.py", line 196, in request
    raise Forbidden(r, data)
discord.errors.Forbidden: FORBIDDEN (status code: 403): Cannot execute action on a DM channel
[31/01/2018 18:15] ERROR red on_command_error 369: Exception in command 'chatter'
Traceback (most recent call last):
  File "lib\discord\ext\commands\core.py", line 50, in wrapped
    ret = yield from coro(*args, **kwargs)
  File "C:\Users\Zak\Documents\Red-DiscordBot-develop\Red-DiscordBot-develop\Red-DiscordBot-develop\cogs\Chatter.py", line 67, in chatter
    await self.bot.delete_message(msgInput)
  File "lib\discord\client.py", line 1262, in delete_message
    yield from self.http.delete_message(channel.id, message.id, guild_id)
  File "lib\discord\http.py", line 196, in request
    raise Forbidden(r, data)
discord.errors.Forbidden: FORBIDDEN (status code: 403): Cannot execute action on a DM channel
